<?xml version="1.0"?>
<robot xmlns:xacro="http://www.ros.org/wiki/xacro" name="my_robot">

<!-- same as minimal robot, except no static link fixing the robot to ground -->
 <!-- Link -->
  <link name="base">
    <collision>
      <origin xyz="0 0 0.99" rpy="0 0 0"/>
      <geometry>
       <box size="0.9 0.7 1.9"/>
      </geometry>
    </collision>

    <visual>
      <origin xyz="0 0 0.99" rpy="0 0 0"/>
      <geometry>
        <box size="0.94 0.78 1.98"/>
      </geometry>
    </visual>
  </link>

  <link name="wheel_center">
    <collision>
      <origin xyz="0 0 0" rpy="0 0 0"/>
      <geometry>
        <cylinder length="0.05" radius="0.15"/>
      </geometry>
    </collision>

    <visual>
      <origin xyz="0 0 0" rpy="0 0 0"/>
      <geometry>
        <cylinder length="0.05" radius="0.15"/>
      </geometry>
    </visual>
  </link>

  <!-- Include the XACRO file that defines a Hokuyo LIDAR. -->
  <xacro:include filename="$(find gazebo_plugins)/test/multi_robot_scenario/xacro/laser/hokuyo.xacro" />
  <xacro:laser name="laser_vert_bottom" parent="base" xyz="0.3157894464801903 -0.002068548615034871 0.5099999434059285" rpy="3.1354753 -1.3045001 0.0024658" meshes="package://gazebo_plugins/test/multi_robot_scenario/meshes/laser" />
  <!--xacro:laser name="laser_vert_bottom" parent="base" xyz="0.3158 -0.0021 0.5100" rpy="3.1355 -1.3045 0.0025" meshes="file://$(find gazebo_plugins)/test/multi_robot_scenario/meshes/laser"/-->
  <xacro:laser name="laser_vert_top_right" parent="base" xyz="0.2978 -0.1450 1.8451" rpy="-1.1760 0.6313 -1.9377" meshes="package://gazebo_plugins/test/multi_robot_scenario/meshes/laser" />
  <xacro:laser name="laser_vert_top_left" parent="base" xyz="0.2997 0.1531 1.8443" rpy="1.1780 0.6198 1.9560" meshes="package://gazebo_plugins/test/multi_robot_scenario/meshes/laser" />
  <!-- Include the XACRO file that defines a Velodyne LIDAR. -->
  <xacro:include filename="$(find velodyne_description)/urdf/VLP-16.urdf.xacro"/>
  <VLP-16 parent="base" name="laser_horiz" topic="laser_horiz/packets" hz="10" samples="440" gpu="false">
    <origin xyz="0.2325416305773505 -0.0001380069427607134 1.920122926231907" rpy="-0.0012068 0.114646 -0.0015308" />
  </VLP-16>

<!-- Joints -->
  <joint name="base_wheel_center" type="continuous">
      <parent link="base"/>
      <child link="wheel_center"/>
      <origin xyz="0.1 0.0 -0.05" rpy="-1.57079632679 0 0"/>
      <limit effort="10.0" lower="0.0" upper="2.0" velocity="0.5"/>
      <axis xyz="0 0 1"/>
  </joint>

  <xacro:macro name="xacro_name" params="suffix reflect">
    <link name="wheel_${suffix}">
      <collision>
        <origin xyz="0 0 0" rpy="0 0 0"/>
        <geometry>
          <cylinder length="0.05" radius="0.2"/>
        </geometry>
      </collision>

      <visual>
        <origin xyz="0 0 0" rpy="0 0 0"/>
        <geometry>
          <cylinder length="0.05" radius="0.2"/>
        </geometry>
      </visual>
    </link>

    <joint name="base_wheel_${suffix}" type="continuous">
      <parent link="base"/>
      <child link="wheel_${suffix}"/>
      <origin xyz="-0.1 ${reflect*0.4} 0.0" rpy="-1.57079632679 0 0"/>
      <axis xyz="0 0 1"/>
      <limit effort="10.0" lower="0.0" upper="2.0" velocity="0.5"/>
    </joint>
  </xacro:macro>

  <xacro:xacro_name suffix="left" reflect="1" />
  <xacro:xacro_name suffix="right" reflect="-1" />
  
</robot>
